Workbook

Sheet mapping_01
A1: KRAINA_EN | B1: MISJA_ID_Z_GRY | C1: MISJA_TYTUL_EN | D1: DODATEK_EN | E1: MISJA_URL_WOWHEAD | F1: NAZWA_LINII_FABULARNEJ_EN | G1: DODANO_W_PATCHU | H1: KONTYNENT_EN | I1: KONTYNENT_PL | J1: KRAINA_PL | K1: DODATEK_PL
A2: Harandar | B2: 86867 | C2: Into the Lightbloom | D2: Midnight | E2: https://www.wowhead.com/quest=86867 | F2: Call of the Goddess | G2: 12.0.0 | H2: =IF(B2="","",_xlfn.XLOOKUP($A2,KONTYNENTY!$A$2:$A$300,KONTYNENTY!$B$2:$B$300,"NoData")) -> Harandar | I2: =IF($B2="","",_xlfn.XLOOKUP($H2,KONTYNENTY!$B$2:$B$300,KONTYNENTY!$C$2:$C$300,"BrakDanych")) -> Harandar | J2: =IF($B2="","", _xlfn.XLOOKUP($A2,KRAINY!$A$2:$A$300,KRAINY!$B$2:$B$300,"BrakDanych")) -> Harandar | K2: =IF(B2="","",D2) -> Midnight
A3: Harandar | B3: 86883 | C3: The Frenzied March | D3: Midnight | E3: https://www.wowhead.com/quest=86883 | F3: Emergence | G3: 12.0.0 | H3: =IF(B3="","",_xlfn.XLOOKUP($A3,KONTYNENTY!$A$2:$A$300,KONTYNENTY!$B$2:$B$300,"NoData")) -> Harandar | I3: =IF($B3="","",_xlfn.XLOOKUP($H3,KONTYNENTY!$B$2:$B$300,KONTYNENTY!$C$2:$C$300,"BrakDanych")) -> Harandar | J3: =IF($B3="","", _xlfn.XLOOKUP($A3,KRAINY!$A$2:$A$300,KRAINY!$B$2:$B$300,"BrakDanych")) -> Harandar | K3: =IF(B3="","",D3) -> Midnight
A4: Harandar | B4: 86881 | C4: At the Root | D4: Midnight | E4: https://www.wowhead.com/quest=86881 | F4: Call of the Goddess | G4: 12.0.0 | H4: =IF(B4="","",_xlfn.XLOOKUP($A4,KONTYNENTY!$A$2:$A$300,KONTYNENTY!$B$2:$B$300,"NoData")) -> Harandar | I4: =IF($B4="","",_xlfn.XLOOKUP($H4,KONTYNENTY!$B$2:$B$300,KONTYNENTY!$C$2:$C$300,"BrakDanych")) -> Harandar | J4: =IF($B4="","", _xlfn.XLOOKUP($A4,KRAINY!$A$2:$A$300,KRAINY!$B$2:$B$300,"BrakDanych")) -> Harandar | K4: =IF(B4="","",D4) -> Midnight
A5: Silvermoon City | B5: 90777 | C5: Feeding the Flame | D5: Midnight | E5: https://www.wowhead.com/quest=90777 | F5: Foothold | G5: 12.0.0 | H5: =IF(B5="","",_xlfn.XLOOKUP($A5,KONTYNENTY!$A$2:$A$300,KONTYNENTY!$B$2:$B$300,"NoData")) -> Eastern Kingdoms | I5: =IF($B5="","",_xlfn.XLOOKUP($H5,KONTYNENTY!$B$2:$B$300,KONTYNENTY!$C$2:$C$300,"BrakDanych")) -> Wschodnie Królestwa | J5: =IF($B5="","", _xlfn.XLOOKUP($A5,KRAINY!$A$2:$A$300,KRAINY!$B$2:$B$300,"BrakDanych")) -> Srebrna Luna | K5: =IF(B5="","",D5) -> Midnight
A6: Voidstorm | B6: 86519 | C6: Abyssus, Abyssum | D6: Midnight | E6: https://www.wowhead.com/quest=86519 | F6: Dawn of Reckoning | G6: 12.0.0 | H6: =IF(B6="","",_xlfn.XLOOKUP($A6,KONTYNENTY!$A$2:$A$300,KONTYNENTY!$B$2:$B$300,"NoData")) -> Great Dark Beyond | I6: =IF($B6="","",_xlfn.XLOOKUP($H6,KONTYNENTY!$B$2:$B$300,KONTYNENTY!$C$2:$C$300,"BrakDanych")) -> Bezkresna Ciemność | J6: =IF($B6="","", _xlfn.XLOOKUP($A6,KRAINY!$A$2:$A$300,KRAINY!$B$2:$B$300,"BrakDanych")) -> Burza Pustki | K6: =IF(B6="","",D6) -> Midnight
A7: Harandar | B7: 86898 | C7: Rise of the Haranir | D7: Midnight | E7: https://www.wowhead.com/quest=86898 | F7: Emergence | G7: 12.0.0 | H7: =IF(B7="","",_xlfn.XLOOKUP($A7,KONTYNENTY!$A$2:$A$300,KONTYNENTY!$B$2:$B$300,"NoData")) -> Harandar | I7: =IF($B7="","",_xlfn.XLOOKUP($H7,KONTYNENTY!$B$2:$B$300,KONTYNENTY!$C$2:$C$300,"BrakDanych")) -> Harandar | J7: =IF($B7="","", _xlfn.XLOOKUP($A7,KRAINY!$A$2:$A$300,KRAINY!$B$2:$B$300,"BrakDanych")) -> Harandar | K7: =IF(B7="","",D7) -> Midnight
A8: Eversong | B8: 88710 | C8: March on Quel'Danas | D8: Midnight | E8: https://www.wowhead.com/quest=88710 | F8: March on Quel'Danas | G8: 12.0.0 | H8: =IF(B8="","",_xlfn.XLOOKUP($A8,KONTYNENTY!$A$2:$A$300,KONTYNENTY!$B$2:$B$300,"NoData")) -> Eastern Kingdoms | I8: =IF($B8="","",_xlfn.XLOOKUP($H8,KONTYNENTY!$B$2:$B$300,KONTYNENTY!$C$2:$C$300,"BrakDanych")) -> Wschodnie Królestwa | J8: =IF($B8="","", _xlfn.XLOOKUP($A8,KRAINY!$A$2:$A$300,KRAINY!$B$2:$B$300,"BrakDanych")) -> Śpiewająca Puszcza | K8: =IF(B8="","",D8) -> Midnight
A9: Arcantina | B9: 92319 | C9: A Favor to Axe | D9: Midnight | E9: https://www.wowhead.com/quest=92319 | F9: The Arcantina | G9: 12.0.0 | H9: =IF(B9="","",_xlfn.XLOOKUP($A9,KONTYNENTY!$A$2:$A$300,KONTYNENTY!$B$2:$B$300,"NoData")) -> Unknown | I9: =IF($B9="","",_xlfn.XLOOKUP($H9,KONTYNENTY!$B$2:$B$300,KONTYNENTY!$C$2:$C$300,"BrakDanych")) -> BrakDanych | J9: =IF($B9="","", _xlfn.XLOOKUP($A9,KRAINY!$A$2:$A$300,KRAINY!$B$2:$B$300,"BrakDanych")) -> Arkantina | K9: =IF(B9="","",D9) -> Midnight
A10: Voidstorm | B10: 90873 | C10: These Violent Delights | D10: Midnight | E10: https://www.wowhead.com/quest=90873 | F10: The Nethersent | G10: 12.0.0 | H10: =IF(B10="","",_xlfn.XLOOKUP($A10,KONTYNENTY!$A$2:$A$300,KONTYNENTY!$B$2:$B$300,"NoData")) -> Great Dark Beyond | I10: =IF($B10="","",_xlfn.XLOOKUP($H10,KONTYNENTY!$B$2:$B$300,KONTYNENTY!$C$2:$C$300,"BrakDanych")) -> Bezkresna Ciemność | J10: =IF($B10="","", _xlfn.XLOOKUP($A10,KRAINY!$A$2:$A$300,KRAINY!$B$2:$B$300,"BrakDanych")) -> Burza Pustki | K10: =IF(B10="","",D10) -> Midnight
A11: Harandar | B11: 86864 | C11: Watch The Den | D11: Midnight | E11: https://www.wowhead.com/quest=86864 | F11: Call of the Goddess | G11: 12.0.0 | H11: =IF(B11="","",_xlfn.XLOOKUP($A11,KONTYNENTY!$A$2:$A$300,KONTYNENTY!$B$2:$B$300,"NoData")) -> Harandar | I11: =IF($B11="","",_xlfn.XLOOKUP($H11,KONTYNENTY!$B$2:$B$300,KONTYNENTY!$C$2:$C$300,"BrakDanych")) -> Harandar | J11: =IF($B11="","", _xlfn.XLOOKUP($A11,KRAINY!$A$2:$A$300,KRAINY!$B$2:$B$300,"BrakDanych")) -> Harandar | K11: =IF(B11="","",D11) -> Midnight
A12: Arcantina | B12: 92321 | C12: A Frostbitten Tally | D12: Midnight | E12: https://www.wowhead.com/quest=92321 | F12: The Arcantina | G12: 12.0.0 | H12: =IF(B12="","",_xlfn.XLOOKUP($A12,KONTYNENTY!$A$2:$A$300,KONTYNENTY!$B$2:$B$300,"NoData")) -> Unknown | I12: =IF($B12="","",_xlfn.XLOOKUP($H12,KONTYNENTY!$B$2:$B$300,KONTYNENTY!$C$2:$C$300,"BrakDanych")) -> BrakDanych | J12: =IF($B12="","", _xlfn.XLOOKUP($A12,KRAINY!$A$2:$A$300,KRAINY!$B$2:$B$300,"BrakDanych")) -> Arkantina | K12: =IF(B12="","",D12) -> Midnight
A13: Harandar | B13: 90534 | C13: The Home of the Haranir | D13: Midnight | E13: https://www.wowhead.com/quest=90534 | F13: A Goblin in Harandar | G13: 12.0.0 | H13: =IF(B13="","",_xlfn.XLOOKUP($A13,KONTYNENTY!$A$2:$A$300,KONTYNENTY!$B$2:$B$300,"NoData")) -> Harandar | I13: =IF($B13="","",_xlfn.XLOOKUP($H13,KONTYNENTY!$B$2:$B$300,KONTYNENTY!$C$2:$C$300,"BrakDanych")) -> Harandar | J13: =IF($B13="","", _xlfn.XLOOKUP($A13,KRAINY!$A$2:$A$300,KRAINY!$B$2:$B$300,"BrakDanych")) -> Harandar | K13: =IF(B13="","",D13) -> Midnight
... A18: Voidstorm | B18: 90875 | C18: Across Worlds | D18: Midnight | E18: https://www.wowhead.com/quest=90875 | F18: The Nethersent | G18: 12.0.0 | H18: =IF(B18="","",_xlfn.XLOOKUP($A18,KONTYNENTY!$A$2:$A$300,KONTYNENTY!$B$2:$B$300,"NoData")) -> Great Dark Beyond | I18: =IF($B18="","",_xlfn.XLOOKUP($H18,KONTYNENTY!$B$2:$B$300,KONTYNENTY!$C$2:$C$300,"BrakDanych")) -> Bezkresna Ciemność | J18: =IF($B18="","", _xlfn.XLOOKUP($A18,KRAINY!$A$2:$A$300,KRAINY!$B$2:$B$300,"BrakDanych")) -> Burza Pustki | K18: =IF(B18="","",D18) -> Midnight
A19: Voidstorm | B19: 93970 | C19: Researching the Storm | D19: Midnight | E19: https://www.wowhead.com/quest=93970 | G19: 12.0.0 | H19: =IF(B19="","",_xlfn.XLOOKUP($A19,KONTYNENTY!$A$2:$A$300,KONTYNENTY!$B$2:$B$300,"NoData")) -> Great Dark Beyond | I19: =IF($B19="","",_xlfn.XLOOKUP($H19,KONTYNENTY!$B$2:$B$300,KONTYNENTY!$C$2:$C$300,"BrakDanych")) -> Bezkresna Ciemność | J19: =IF($B19="","", _xlfn.XLOOKUP($A19,KRAINY!$A$2:$A$300,KRAINY!$B$2:$B$300,"BrakDanych")) -> Burza Pustki | K19: =IF(B19="","",D19) -> Midnight
A20: Harandar | B20: 88994 | C20: The Cauldron of Echoes | D20: Midnight | E20: https://www.wowhead.com/quest=88994 | F20: Legends Relics | G20: 12.0.0 | H20: =IF(B20="","",_xlfn.XLOOKUP($A20,KONTYNENTY!$A$2:$A$300,KONTYNENTY!$B$2:$B$300,"NoData")) -> Harandar | I20: =IF($B20="","",_xlfn.XLOOKUP($H20,KONTYNENTY!$B$2:$B$300,KONTYNENTY!$C$2:$C$300,"BrakDanych")) -> Harandar | J20: =IF($B20="","", _xlfn.XLOOKUP($A20,KRAINY!$A$2:$A$300,KRAINY!$B$2:$B$300,"BrakDanych")) -> Harandar | K20: =IF(B20="","",D20) -> Midnight
A21: Voidstorm | B21: 86517 | C21: Vanished in the Void | D21: Midnight | E21: https://www.wowhead.com/quest=86517 | F21: Dawn of Reckoning | G21: 12.0.0 | H21: =IF(B21="","",_xlfn.XLOOKUP($A21,KONTYNENTY!$A$2:$A$300,KONTYNENTY!$B$2:$B$300,"NoData")) -> Great Dark Beyond | I21: =IF($B21="","",_xlfn.XLOOKUP($H21,KONTYNENTY!$B$2:$B$300,KONTYNENTY!$C$2:$C$300,"BrakDanych")) -> Bezkresna Ciemność | J21: =IF($B21="","", _xlfn.XLOOKUP($A21,KRAINY!$A$2:$A$300,KRAINY!$B$2:$B$300,"BrakDanych")) -> Burza Pustki | K21: =IF(B21="","",D21) -> Midnight
A22: Voidstorm | B22: 89388 | C22: Voidstorm | D22: Midnight | E22: https://www.wowhead.com/quest=89388 | F22: Into the Abyss | G22: 12.0.0 | H22: =IF(B22="","",_xlfn.XLOOKUP($A22,KONTYNENTY!$A$2:$A$300,KONTYNENTY!$B$2:$B$300,"NoData")) -> Great Dark Beyond | I22: =IF($B22="","",_xlfn.XLOOKUP($H22,KONTYNENTY!$B$2:$B$300,KONTYNENTY!$C$2:$C$300,"BrakDanych")) -> Bezkresna Ciemność | J22: =IF($B22="","", _xlfn.XLOOKUP($A22,KRAINY!$A$2:$A$300,KRAINY!$B$2:$B$300,"BrakDanych")) -> Burza Pustki | K22: =IF(B22="","",D22) -> Midnight
A23: Arator's Journey | B23: 86837 | C23: Meet at the Sunwell | D23: Midnight | E23: https://www.wowhead.com/quest=86837 | F23: The Path of Light | G23: 12.0.0 | H23: =IF(B23="","",_xlfn.XLOOKUP($A23,KONTYNENTY!$A$2:$A$300,KONTYNENTY!$B$2:$B$300,"NoData")) -> Unknown | I23: =IF($B23="","",_xlfn.XLOOKUP($H23,KONTYNENTY!$B$2:$B$300,KONTYNENTY!$C$2:$C$300,"BrakDanych")) -> BrakDanych | J23: =IF($B23="","", _xlfn.XLOOKUP($A23,KRAINY!$A$2:$A$300,KRAINY!$B$2:$B$300,"BrakDanych")) -> Podróże Aratora | K23: =IF(B23="","",D23) -> Midnight
A24: Dungeon | B24: 93755 | C24: Den of Nalorakk | D24: Midnight | E24: https://www.wowhead.com/quest=93755 | G24: 12.0.0 | H24: =IF(B24="","",_xlfn.XLOOKUP($A24,KONTYNENTY!$A$2:$A$300,KONTYNENTY!$B$2:$B$300,"NoData")) -> Instance | I24: =IF($B24="","",_xlfn.XLOOKUP($H24,KONTYNENTY!$B$2:$B$300,KONTYNENTY!$C$2:$C$300,"BrakDanych")) -> Loch | J24: =IF($B24="","", _xlfn.XLOOKUP($A24,KRAINY!$A$2:$A$300,KRAINY!$B$2:$B$300,"BrakDanych")) -> Loch | K24: =IF(B24="","",D24) -> Midnight
A25: Arcantina | B25: 92325 | C25: Hellscream's Heritage | D25: Midnight | E25: https://www.wowhead.com/quest=92325 | F25: The Arcantina | G25: 12.0.0 | H25: =IF(B25="","",_xlfn.XLOOKUP($A25,KONTYNENTY!$A$2:$A$300,KONTYNENTY!$B$2:$B$300,"NoData")) -> Unknown | I25: =IF($B25="","",_xlfn.XLOOKUP($H25,KONTYNENTY!$B$2:$B$300,KONTYNENTY!$C$2:$C$300,"BrakDanych")) -> BrakDanych | J25: =IF($B25="","", _xlfn.XLOOKUP($A25,KRAINY!$A$2:$A$300,KRAINY!$B$2:$B$300,"BrakDanych")) -> Arkantina | K25: =IF(B25="","",D25) -> Midnight
A26: Voidstorm | B26: 86521 | C26: Nexus-Point Xenas: Eclipse | D26: Midnight | E26: https://www.wowhead.com/quest=86521 | F26: Dawn of Reckoning | G26: 12.0.0 | H26: =IF(B26="","",_xlfn.XLOOKUP($A26,KONTYNENTY!$A$2:$A$300,KONTYNENTY!$B$2:$B$300,"NoData")) -> Great Dark Beyond | I26: =IF($B26="","",_xlfn.XLOOKUP($H26,KONTYNENTY!$B$2:$B$300,KONTYNENTY!$C$2:$C$300,"BrakDanych")) -> Bezkresna Ciemność | J26: =IF($B26="","", _xlfn.XLOOKUP($A26,KRAINY!$A$2:$A$300,KRAINY!$B$2:$B$300,"BrakDanych")) -> Burza Pustki | K26: =IF(B26="","",D26) -> Midnight
A27: Storm Fields | B27: 92948 | C27: In Over My Head | D27: Midnight | E27: https://www.wowhead.com/quest=92948 | F27: Written by the Winners | G27: 12.0.0 | H27: =IF(B27="","",_xlfn.XLOOKUP($A27,KONTYNENTY!$A$2:$A$300,KONTYNENTY!$B$2:$B$300,"NoData")) -> Unknown | I27: =IF($B27="","",_xlfn.XLOOKUP($H27,KONTYNENTY!$B$2:$B$300,KONTYNENTY!$C$2:$C$300,"BrakDanych")) -> BrakDanych | J27: =IF($B27="","", _xlfn.XLOOKUP($A27,KRAINY!$A$2:$A$300,KRAINY!$B$2:$B$300,"BrakDanych")) -> Storm Fields | K27: =IF(B27="","",D27) -> Midnight
A28: Meta Quests | B28: 93909 | C28: Midnight: Delves | D28: Midnight | E28: https://www.wowhead.com/quest=93909 | G28: 12.0.0 | H28: =IF(B28="","",_xlfn.XLOOKUP($A28,KONTYNENTY!$A$2:$A$300,KONTYNENTY!$B$2:$B$300,"NoData")) -> Meta Quests | I28: =IF($B28="","",_xlfn.XLOOKUP($H28,KONTYNENTY!$B$2:$B$300,KONTYNENTY!$C$2:$C$300,"BrakDanych")) -> Meta Misje | J28: =IF($B28="","", _xlfn.XLOOKUP($A28,KRAINY!$A$2:$A$300,KRAINY!$B$2:$B$300,"BrakDanych")) -> Meta Misje | K28: =IF(B28="","",D28) -> Midnight
A29: Harandar | B29: 90533 | C29: Go Get Orweyna! | D29: Midnight | E29: https://www.wowhead.com/quest=90533 | F29: A Goblin in Harandar | G29: 12.0.0 | H29: =IF(B29="","",_xlfn.XLOOKUP($A29,KONTYNENTY!$A$2:$A$300,KONTYNENTY!$B$2:$B$300,"NoData")) -> Harandar | I29: =IF($B29="","",_xlfn.XLOOKUP($H29,KONTYNENTY!$B$2:$B$300,KONTYNENTY!$C$2:$C$300,"BrakDanych")) -> Harandar | J29: =IF($B29="","", _xlfn.XLOOKUP($A29,KRAINY!$A$2:$A$300,KRAINY!$B$2:$B$300,"BrakDanych")) -> Harandar | K29: =IF(B29="","",D29) -> Midnight
A30: Silvermoon City | B30: 88696 | C30: The Devouring Citadel | D30: Midnight | E30: https://www.wowhead.com/quest=88696 | F30: Foothold | G30: 12.0.0 | H30: =IF(B30="","",_xlfn.XLOOKUP($A30,KONTYNENTY!$A$2:$A$300,KONTYNENTY!$B$2:$B$300,"NoData")) -> Eastern Kingdoms | I30: =IF($B30="","",_xlfn.XLOOKUP($H30,KONTYNENTY!$B$2:$B$300,KONTYNENTY!$C$2:$C$300,"BrakDanych")) -> Wschodnie Królestwa | J30: =IF($B30="","", _xlfn.XLOOKUP($A30,KRAINY!$A$2:$A$300,KRAINY!$B$2:$B$300,"BrakDanych")) -> Srebrna Luna | K30: =IF(B30="","",D30) -> Midnight
A31: Arcantina | B31: 92322 | C31: Timear Foresees a Proof of Demise! | D31: Midnight | E31: https://www.wowhead.com/quest=92322 | F31: The Arcantina | G31: 12.0.0 | H31: =IF(B31="","",_xlfn.XLOOKUP($A31,KONTYNENTY!$A$2:$A$300,KONTYNENTY!$B$2:$B$300,"NoData")) -> Unknown | I31: =IF($B31="","",_xlfn.XLOOKUP($H31,KONTYNENTY!$B$2:$B$300,KONTYNENTY!$C$2:$C$300,"BrakDanych")) -> BrakDanych | J31: =IF($B31="","", _xlfn.XLOOKUP($A31,KRAINY!$A$2:$A$300,KRAINY!$B$2:$B$300,"BrakDanych")) -> Arkantina | K31: =IF(B31="","",D31) -> Midnight
A32: Harandar | B32: 86944 | C32: Seeds of the Rift | D32: Midnight | E32: https://www.wowhead.com/quest=86944 | F32: Of Caves and Cradles | G32: 12.0.0 | H32: =IF(B32="","",_xlfn.XLOOKUP($A32,KONTYNENTY!$A$2:$A$300,KONTYNENTY!$B$2:$B$300,"NoData")) -> Harandar | I32: =IF($B32="","",_xlfn.XLOOKUP($H32,KONTYNENTY!$B$2:$B$300,KONTYNENTY!$C$2:$C$300,"BrakDanych")) -> Harandar | J32: =IF($B32="","", _xlfn.XLOOKUP($A32,KRAINY!$A$2:$A$300,KRAINY!$B$2:$B$300,"BrakDanych")) -> Harandar | K32: =IF(B32="","",D32) -> Midnight
A33: Voidstorm | B33: 86528 | C33: A Cracked Holokey | D33: Midnight | E33: https://www.wowhead.com/quest=86528 | F33: The Night's Veil | G33: 12.0.0 | H33: =IF(B33="","",_xlfn.XLOOKUP($A33,KONTYNENTY!$A$2:$A$300,KONTYNENTY!$B$2:$B$300,"NoData")) -> Great Dark Beyond | I33: =IF($B33="","",_xlfn.XLOOKUP($H33,KONTYNENTY!$B$2:$B$300,KONTYNENTY!$C$2:$C$300,"BrakDanych")) -> Bezkresna Ciemność | J33: =IF($B33="","", _xlfn.XLOOKUP($A33,KRAINY!$A$2:$A$300,KRAINY!$B$2:$B$300,"BrakDanych")) -> Burza Pustki | K33: =IF(B33="","",D33) -> Midnight
A34: Voidstorm | B34: 90924 | C34: The Wicked End | D34: Midnight | E34: https://www.wowhead.com/quest=90924 | F34: Dance with the Devil | G34: 12.0.0 | H34: =IF(B34="","",_xlfn.XLOOKUP($A34,KONTYNENTY!$A$2:$A$300,KONTYNENTY!$B$2:$B$300,"NoData")) -> Great Dark Beyond | I34: =IF($B34="","",_xlfn.XLOOKUP($H34,KONTYNENTY!$B$2:$B$300,KONTYNENTY!$C$2:$C$300,"BrakDanych")) -> Bezkresna Ciemność | J34: =IF($B34="","", _xlfn.XLOOKUP($A34,KRAINY!$A$2:$A$300,KRAINY!$B$2:$B$300,"BrakDanych")) -> Burza Pustki | K34: =IF(B34="","",D34) -> Midnight
A35: Voidstorm | B35: 93573 | C35: Deciphering Darkness | D35: Midnight | E35: https://www.wowhead.com/quest=93573 | G35: 12.0.0 | H35: =IF(B35="","",_xlfn.XLOOKUP($A35,KONTYNENTY!$A$2:$A$300,KONTYNENTY!$B$2:$B$300,"NoData")) -> Great Dark Beyond | I35: =IF($B35="","",_xlfn.XLOOKUP($H35,KONTYNENTY!$B$2:$B$300,KONTYNENTY!$C$2:$C$300,"BrakDanych")) -> Bezkresna Ciemność | J35: =IF($B35="","", _xlfn.XLOOKUP($A35,KRAINY!$A$2:$A$300,KRAINY!$B$2:$B$300,"BrakDanych")) -> Burza Pustki | K35: =IF(B35="","",D35) -> Midnight
A36: Prey | B36: 91102 | C36: Prey: Nexus-Edge Hadim (Normal) | D36: Midnight | E36: https://www.wowhead.com/quest=91102 | F36: Prey | G36: 12.0.0 | H36: =IF(B36="","",_xlfn.XLOOKUP($A36,KONTYNENTY!$A$2:$A$300,KONTYNENTY!$B$2:$B$300,"NoData")) -> Prey | I36: =IF($B36="","",_xlfn.XLOOKUP($H36,KONTYNENTY!$B$2:$B$300,KONTYNENTY!$C$2:$C$300,"BrakDanych")) -> Zwierzyna | J36: =IF($B36="","", _xlfn.XLOOKUP($A36,KRAINY!$A$2:$A$300,KRAINY!$B$2:$B$300,"BrakDanych")) -> Zwierzyna | K36: =IF(B36="","",D36) -> Midnight
A37: Arcantina | B37: 92320 | C37: Still Behind Enemy Portals | D37: Midnight | E37: https://www.wowhead.com/quest=92320 | F37: The Arcantina | G37: 12.0.0 | H37: =IF(B37="","",_xlfn.XLOOKUP($A37,KONTYNENTY!$A$2:$A$300,KONTYNENTY!$B$2:$B$300,"NoData")) -> Unknown | I37: =IF($B37="","",_xlfn.XLOOKUP($H37,KONTYNENTY!$B$2:$B$300,KONTYNENTY!$C$2:$C$300,"BrakDanych")) -> BrakDanych | J37: =IF($B37="","", _xlfn.XLOOKUP($A37,KRAINY!$A$2:$A$300,KRAINY!$B$2:$B$300,"BrakDanych")) -> Arkantina | K37: =IF(B37="","",D37) -> Midnight
A38: Harandar | B38: 90734 | C38: In the Name of the Goddess | D38: Midnight | E38: https://www.wowhead.com/quest=90734 | F38: The Empty Cradle | G38: 12.0.0 | H38: =IF(B38="","",_xlfn.XLOOKUP($A38,KONTYNENTY!$A$2:$A$300,KONTYNENTY!$B$2:$B$300,"NoData")) -> Harandar | I38: =IF($B38="","",_xlfn.XLOOKUP($H38,KONTYNENTY!$B$2:$B$300,KONTYNENTY!$C$2:$C$300,"BrakDanych")) -> Harandar | J38: =IF($B38="","", _xlfn.XLOOKUP($A38,KRAINY!$A$2:$A$300,KRAINY!$B$2:$B$300,"BrakDanych")) -> Harandar | K38: =IF(B38="","",D38) -> Midnight
A39: Arcantina | B39: 92326 | C39: The Fragrance of the Dunes | D39: Midnight | E39: https://www.wowhead.com/quest=92326 | F39: The Arcantina | G39: 12.0.0 | H39: =IF(B39="","",_xlfn.XLOOKUP($A39,KONTYNENTY!$A$2:$A$300,KONTYNENTY!$B$2:$B$300,"NoData")) -> Unknown | I39: =IF($B39="","",_xlfn.XLOOKUP($H39,KONTYNENTY!$B$2:$B$300,KONTYNENTY!$C$2:$C$300,"BrakDanych")) -> BrakDanych | J39: =IF($B39="","", _xlfn.XLOOKUP($A39,KRAINY!$A$2:$A$300,KRAINY!$B$2:$B$300,"BrakDanych")) -> Arkantina | K39: =IF(B39="","",D39) -> Midnight
A40: Voidstorm | B40: 86514 | C40: Lady of the Pit | D40: Midnight | E40: https://www.wowhead.com/quest=86514 | F40: Dawn of Reckoning | G40: 12.0.0 | H40: =IF(B40="","",_xlfn.XLOOKUP($A40,KONTYNENTY!$A$2:$A$300,KONTYNENTY!$B$2:$B$300,"NoData")) -> Great Dark Beyond | I40: =IF($B40="","",_xlfn.XLOOKUP($H40,KONTYNENTY!$B$2:$B$300,KONTYNENTY!$C$2:$C$300,"BrakDanych")) -> Bezkresna Ciemność | J40: =IF($B40="","", _xlfn.XLOOKUP($A40,KRAINY!$A$2:$A$300,KRAINY!$B$2:$B$300,"BrakDanych")) -> Burza Pustki | K40: =IF(B40="","",D40) -> Midnight
A41: Voidstorm | B41: 90866 | C41: Universal Language | D41: Midnight | E41: https://www.wowhead.com/quest=90866 | F41: The Nethersent | G41: 12.0.0 | H41: =IF(B41="","",_xlfn.XLOOKUP($A41,KONTYNENTY!$A$2:$A$300,KONTYNENTY!$B$2:$B$300,"NoData")) -> Great Dark Beyond | I41: =IF($B41="","",_xlfn.XLOOKUP($H41,KONTYNENTY!$B$2:$B$300,KONTYNENTY!$C$2:$C$300,"BrakDanych")) -> Bezkresna Ciemność | J41: =IF($B41="","", _xlfn.XLOOKUP($A41,KRAINY!$A$2:$A$300,KRAINY!$B$2:$B$300,"BrakDanych")) -> Burza Pustki | K41: =IF(B41="","",D41) -> Midnight
A42: Prey | B42: 93043 | C42: When Predator Becomes Prey | D42: Midnight | E42: https://www.wowhead.com/quest=93043 | F42: Prey | G42: 12.0.0 | H42: =IF(B42="","",_xlfn.XLOOKUP($A42,KONTYNENTY!$A$2:$A$300,KONTYNENTY!$B$2:$B$300,"NoData")) -> Prey | I42: =IF($B42="","",_xlfn.XLOOKUP($H42,KONTYNENTY!$B$2:$B$300,KONTYNENTY!$C$2:$C$300,"BrakDanych")) -> Zwierzyna | J42: =IF($B42="","", _xlfn.XLOOKUP($A42,KRAINY!$A$2:$A$300,KRAINY!$B$2:$B$300,"BrakDanych")) -> Zwierzyna | K42: =IF(B42="","",D42) -> Midnight
A43: Abundance | B43: 94361 | C43: The Abundant Life | D43: Midnight | E43: https://www.wowhead.com/quest=94361 | F43: Abundance | G43: 12.0.0 | H43: =IF(B43="","",_xlfn.XLOOKUP($A43,KONTYNENTY!$A$2:$A$300,KONTYNENTY!$B$2:$B$300,"NoData")) -> Abundance | I43: =IF($B43="","",_xlfn.XLOOKUP($H43,KONTYNENTY!$B$2:$B$300,KONTYNENTY!$C$2:$C$300,"BrakDanych")) -> Abundance | J43: =IF($B43="","", _xlfn.XLOOKUP($A43,KRAINY!$A$2:$A$300,KRAINY!$B$2:$B$300,"BrakDanych")) -> Abundance | K43: =IF(B43="","",D43) -> Midnight
A44: Harandar | B44: 91359 | C44: Fungal Lashers B Gone | D44: Midnight | E44: https://www.wowhead.com/quest=91359 | F44: The Greenspeaker's Vigil | G44: 12.0.0 | H44: =IF(B44="","",_xlfn.XLOOKUP($A44,KONTYNENTY!$A$2:$A$300,KONTYNENTY!$B$2:$B$300,"NoData")) -> Harandar | I44: =IF($B44="","",_xlfn.XLOOKUP($H44,KONTYNENTY!$B$2:$B$300,KONTYNENTY!$C$2:$C$300,"BrakDanych")) -> Harandar | J44: =IF($B44="","", _xlfn.XLOOKUP($A44,KRAINY!$A$2:$A$300,KRAINY!$B$2:$B$300,"BrakDanych")) -> Harandar | K44: =IF(B44="","",D44) -> Midnight
...

Sheet KONTYNENTY
A1: KRAINA_EN | B1: KONTYNENT_EN | C1: KONTYNENT_PL
A2: Harandar | B2: Harandar | C2: Harandar
A3: Silvermoon City | B3: Eastern Kingdoms | C3: Wschodnie Królestwa
A4: Voidstorm | B4: Great Dark Beyond | C4: Bezkresna Ciemność
A5: Eversong | B5: Eastern Kingdoms | C5: Wschodnie Królestwa
A6: Arcantina | B6: Unknown | C6: BrakDanych
A7: Arator's Journey | B7: Unknown | C7: BrakDanych
A8: Dungeon | B8: Instance | C8: Loch
A9: Storm Fields | B9: Unknown | C9: BrakDanych
A10: Meta Quests | B10: Meta Quests | C10: Meta Misje
A11: Prey | B11: Prey | C11: Zwierzyna
A12: Abundance | B12: Abundance | C12: Abundance
... A45: Eversong Woods (Burning Crusade) | B45: Eastern Kingdoms | C45: Wschodnie Królestwa

Sheet KRAINY
A1: KRAINA_EN | B1: KRAINA_PL
A2: Harandar | B2: Harandar
A3: Silvermoon City | B3: Srebrna Luna
A4: Voidstorm | B4: Burza Pustki
A5: Eversong | B5: Śpiewająca Puszcza
A6: Arcantina | B6: Arkantina
A7: Arator's Journey | B7: Podróże Aratora
A8: Dungeon | B8: Loch
A9: Storm Fields | B9: Storm Fields
A10: Meta Quests | B10: Meta Misje
A11: Prey | B11: Zwierzyna
A12: Abundance | B12: Abundance
... A53: Elrendar River | B53: Rzeka Elrendar

Sheet DODATKI
A1: DODATEK_EN | B1: DODATEK_PL
A2: Midnght | B2: Północ
A3: The War Within | B3: Wewnętrzna Wojna
